2025-07-17 15:52:04,990 INFO: Microblog startup [in C:\Users\USUARIO\Desktop\clone-blog\blog_1\app\__init__.py:43]
2025-07-17 15:56:17,801 INFO: Microblog startup [in C:\Users\USUARIO\Desktop\clone-blog\blog_1\app\__init__.py:43]
2025-07-17 15:56:35,579 INFO: Microblog startup [in C:\Users\USUARIO\Desktop\clone-blog\blog_1\app\__init__.py:43]
2025-07-22 17:10:12,281 INFO: Microblog startup [in C:\Users\USUARIO\Desktop\clone-blog\blog_1\app\__init__.py:43]
2025-07-22 17:10:31,702 INFO: Microblog startup [in C:\Users\USUARIO\Desktop\clone-blog\blog_1\app\__init__.py:43]
2025-07-22 17:11:34,126 ERROR: Exception on /register [POST] [in C:\Users\USUARIO\AppData\Local\Programs\Python\Python313\Lib\site-packages\flask\app.py:875]
Traceback (most recent call last):
  File "C:\Users\USUARIO\AppData\Local\Programs\Python\Python313\Lib\site-packages\wtforms\validators.py", line 401, in __call__
    import email_validator
ModuleNotFoundError: No module named 'email_validator'

The above exception was the direct cause of the following exception:

Traceback (most recent call last):
  File "C:\Users\USUARIO\AppData\Local\Programs\Python\Python313\Lib\site-packages\flask\app.py", line 1511, in wsgi_app
    response = self.full_dispatch_request()
  File "C:\Users\USUARIO\AppData\Local\Programs\Python\Python313\Lib\site-packages\flask\app.py", line 919, in full_dispatch_request
    rv = self.handle_user_exception(e)
  File "C:\Users\USUARIO\AppData\Local\Programs\Python\Python313\Lib\site-packages\flask\app.py", line 917, in full_dispatch_request
    rv = self.dispatch_request()
  File "C:\Users\USUARIO\AppData\Local\Programs\Python\Python313\Lib\site-packages\flask\app.py", line 902, in dispatch_request
    return self.ensure_sync(self.view_functions[rule.endpoint])(**view_args)  # type: ignore[no-any-return]
           ~~~~~~~~~~~~~~~~~~~~~~~~~~~~~~~~~~~~~~~~~~~~~~~~~~~~^^^^^^^^^^^^^
  File "C:\Users\USUARIO\Desktop\clone-blog\blog_1\app\routes.py", line 55, in register
    if form.validate_on_submit():
       ~~~~~~~~~~~~~~~~~~~~~~~^^
  File "C:\Users\USUARIO\AppData\Local\Programs\Python\Python313\Lib\site-packages\flask_wtf\form.py", line 86, in validate_on_submit
    return self.is_submitted() and self.validate(extra_validators=extra_validators)
                                   ~~~~~~~~~~~~~^^^^^^^^^^^^^^^^^^^^^^^^^^^^^^^^^^^
  File "C:\Users\USUARIO\AppData\Local\Programs\Python\Python313\Lib\site-packages\wtforms\form.py", line 330, in validate
    return super().validate(extra)
           ~~~~~~~~~~~~~~~~^^^^^^^
  File "C:\Users\USUARIO\AppData\Local\Programs\Python\Python313\Lib\site-packages\wtforms\form.py", line 147, in validate
    if not field.validate(self, extra):
           ~~~~~~~~~~~~~~^^^^^^^^^^^^^
  File "C:\Users\USUARIO\AppData\Local\Programs\Python\Python313\Lib\site-packages\wtforms\fields\core.py", line 234, in validate
    stop_validation = self._run_validation_chain(form, chain)
  File "C:\Users\USUARIO\AppData\Local\Programs\Python\Python313\Lib\site-packages\wtforms\fields\core.py", line 254, in _run_validation_chain
    validator(form, self)
    ~~~~~~~~~^^^^^^^^^^^^
  File "C:\Users\USUARIO\AppData\Local\Programs\Python\Python313\Lib\site-packages\wtforms\validators.py", line 403, in __call__
    raise Exception(
        "Install 'email_validator' for email validation support."
    ) from exc
Exception: Install 'email_validator' for email validation support.
2025-07-22 17:39:01,640 ERROR: Exception on /register [POST] [in C:\Users\USUARIO\AppData\Local\Programs\Python\Python313\Lib\site-packages\flask\app.py:875]
Traceback (most recent call last):
  File "C:\Users\USUARIO\AppData\Local\Programs\Python\Python313\Lib\site-packages\wtforms\validators.py", line 401, in __call__
    import email_validator
ModuleNotFoundError: No module named 'email_validator'

The above exception was the direct cause of the following exception:

Traceback (most recent call last):
  File "C:\Users\USUARIO\AppData\Local\Programs\Python\Python313\Lib\site-packages\flask\app.py", line 1511, in wsgi_app
    response = self.full_dispatch_request()
  File "C:\Users\USUARIO\AppData\Local\Programs\Python\Python313\Lib\site-packages\flask\app.py", line 919, in full_dispatch_request
    rv = self.handle_user_exception(e)
  File "C:\Users\USUARIO\AppData\Local\Programs\Python\Python313\Lib\site-packages\flask\app.py", line 917, in full_dispatch_request
    rv = self.dispatch_request()
  File "C:\Users\USUARIO\AppData\Local\Programs\Python\Python313\Lib\site-packages\flask\app.py", line 902, in dispatch_request
    return self.ensure_sync(self.view_functions[rule.endpoint])(**view_args)  # type: ignore[no-any-return]
           ~~~~~~~~~~~~~~~~~~~~~~~~~~~~~~~~~~~~~~~~~~~~~~~~~~~~^^^^^^^^^^^^^
  File "C:\Users\USUARIO\Desktop\clone-blog\blog_1\app\routes.py", line 55, in register
    if form.validate_on_submit():
       ~~~~~~~~~~~~~~~~~~~~~~~^^
  File "C:\Users\USUARIO\AppData\Local\Programs\Python\Python313\Lib\site-packages\flask_wtf\form.py", line 86, in validate_on_submit
    return self.is_submitted() and self.validate(extra_validators=extra_validators)
                                   ~~~~~~~~~~~~~^^^^^^^^^^^^^^^^^^^^^^^^^^^^^^^^^^^
  File "C:\Users\USUARIO\AppData\Local\Programs\Python\Python313\Lib\site-packages\wtforms\form.py", line 330, in validate
    return super().validate(extra)
           ~~~~~~~~~~~~~~~~^^^^^^^
  File "C:\Users\USUARIO\AppData\Local\Programs\Python\Python313\Lib\site-packages\wtforms\form.py", line 147, in validate
    if not field.validate(self, extra):
           ~~~~~~~~~~~~~~^^^^^^^^^^^^^
  File "C:\Users\USUARIO\AppData\Local\Programs\Python\Python313\Lib\site-packages\wtforms\fields\core.py", line 234, in validate
    stop_validation = self._run_validation_chain(form, chain)
  File "C:\Users\USUARIO\AppData\Local\Programs\Python\Python313\Lib\site-packages\wtforms\fields\core.py", line 254, in _run_validation_chain
    validator(form, self)
    ~~~~~~~~~^^^^^^^^^^^^
  File "C:\Users\USUARIO\AppData\Local\Programs\Python\Python313\Lib\site-packages\wtforms\validators.py", line 403, in __call__
    raise Exception(
        "Install 'email_validator' for email validation support."
    ) from exc
Exception: Install 'email_validator' for email validation support.
2025-07-24 14:38:22,972 INFO: Microblog startup [in C:\Users\USUARIO\Desktop\clone-blog\blog_1\app\__init__.py:43]
2025-07-24 15:24:29,452 INFO: Microblog startup [in C:\Users\USUARIO\Desktop\clone-blog\blog_1\app\__init__.py:43]
2025-07-24 15:28:19,473 ERROR: Exception on /register [POST] [in C:\Users\USUARIO\AppData\Local\Programs\Python\Python313\Lib\site-packages\flask\app.py:875]
Traceback (most recent call last):
  File "C:\Users\USUARIO\AppData\Local\Programs\Python\Python313\Lib\site-packages\wtforms\validators.py", line 401, in __call__
    import email_validator
ModuleNotFoundError: No module named 'email_validator'

The above exception was the direct cause of the following exception:

Traceback (most recent call last):
  File "C:\Users\USUARIO\AppData\Local\Programs\Python\Python313\Lib\site-packages\flask\app.py", line 1511, in wsgi_app
    response = self.full_dispatch_request()
  File "C:\Users\USUARIO\AppData\Local\Programs\Python\Python313\Lib\site-packages\flask\app.py", line 919, in full_dispatch_request
    rv = self.handle_user_exception(e)
  File "C:\Users\USUARIO\AppData\Local\Programs\Python\Python313\Lib\site-packages\flask\app.py", line 917, in full_dispatch_request
    rv = self.dispatch_request()
  File "C:\Users\USUARIO\AppData\Local\Programs\Python\Python313\Lib\site-packages\flask\app.py", line 902, in dispatch_request
    return self.ensure_sync(self.view_functions[rule.endpoint])(**view_args)  # type: ignore[no-any-return]
           ~~~~~~~~~~~~~~~~~~~~~~~~~~~~~~~~~~~~~~~~~~~~~~~~~~~~^^^^^^^^^^^^^
  File "C:\Users\USUARIO\Desktop\clone-blog\blog_1\app\routes.py", line 55, in register
    if form.validate_on_submit():
       ~~~~~~~~~~~~~~~~~~~~~~~^^
  File "C:\Users\USUARIO\AppData\Local\Programs\Python\Python313\Lib\site-packages\flask_wtf\form.py", line 86, in validate_on_submit
    return self.is_submitted() and self.validate(extra_validators=extra_validators)
                                   ~~~~~~~~~~~~~^^^^^^^^^^^^^^^^^^^^^^^^^^^^^^^^^^^
  File "C:\Users\USUARIO\AppData\Local\Programs\Python\Python313\Lib\site-packages\wtforms\form.py", line 330, in validate
    return super().validate(extra)
           ~~~~~~~~~~~~~~~~^^^^^^^
  File "C:\Users\USUARIO\AppData\Local\Programs\Python\Python313\Lib\site-packages\wtforms\form.py", line 147, in validate
    if not field.validate(self, extra):
           ~~~~~~~~~~~~~~^^^^^^^^^^^^^
  File "C:\Users\USUARIO\AppData\Local\Programs\Python\Python313\Lib\site-packages\wtforms\fields\core.py", line 234, in validate
    stop_validation = self._run_validation_chain(form, chain)
  File "C:\Users\USUARIO\AppData\Local\Programs\Python\Python313\Lib\site-packages\wtforms\fields\core.py", line 254, in _run_validation_chain
    validator(form, self)
    ~~~~~~~~~^^^^^^^^^^^^
  File "C:\Users\USUARIO\AppData\Local\Programs\Python\Python313\Lib\site-packages\wtforms\validators.py", line 403, in __call__
    raise Exception(
        "Install 'email_validator' for email validation support."
    ) from exc
Exception: Install 'email_validator' for email validation support.
2025-07-29 16:54:09,965 INFO: Microblog startup [in C:\Users\USUARIO\Desktop\clone-blog\blog_1\app\__init__.py:43]
